Workbook

Sheet Bilan IFRS
A1: Bilan IFRS — Exercice 2
A2: Société « X » (cotée en bourse) — au 31/12/2014 (montants nets, en dirhams marocains) — présentation IAS 1 courant / non courant
A4: Référence | B4: Poste | C4: Montant net
B5: ACTIFS NON COURANTS
A6: IAS 16 | B6: Immobilisations corporelles (terrains, ITMO, transport, mobilier) | C6: =Calculs!D7+Calculs!D9+Calculs!D10+Calculs!D11 -> 5000000
A7: IAS 40 | B7: Immeubles de placement (constructions louées à des tiers) | C7: =Calculs!D8 -> 1280000
A8: IAS 38 | B8: Immobilisations incorporelles (brevets, marques, droits) | C8: =Calculs!D6 -> 1120000
A9: IFRS 9 | B9: Titres de participation | C9: =Calculs!D12 -> 1000000
A10: IFRS 9 | B10: Prêt à la filiale – part à plus d’un an | C10: =Calculs!D13-Calculs!D35 -> 500000
B11: Total actifs non courants | C11: =SUM(C6:C10) -> 8900000
B12: ACTIFS COURANTS (HORS TRÉSORERIE)
A13: IAS 2 | B13: Stocks (nets de dépréciation) | C13: =Calculs!D14+Calculs!D15+Calculs!D16 -> 775000
A14: IFRS 9 | B14: Clients et comptes rattachés (nets de dépréciation) | C14: =Calculs!D17 -> 2650000
A15: IAS 1 | B15: Charges constatées d’avance | C15: =Calculs!D18 -> 18000
A16: IFRS 9 | B16: Prêt à la filiale – part à moins d’un an | C16: =Calculs!D35 -> 200000
B17: Total actifs courants | C17: =SUM(C13:C16) -> 3643000
B18: TRÉSORERIE ET ÉQUIVALENTS DE TRÉSORERIE
A19: IAS 7 | B19: Banque | C19: =Calculs!D19 -> 1200000
A20: IAS 7 | B20: Caisse | C20: =Calculs!D20 -> 250000
B21: Total trésorerie – actif | C21: =SUM(C19:C20) -> 1450000
B22: TOTAL DE L’ACTIF | C22: =C11+C17+C21 -> 13993000
B24: CAPITAUX PROPRES – PART DU GROUPE
A25: IAS 1 | B25: Capital social | C25: =Calculs!D24 -> 9000000
A26: IAS 1 | B26: Réserve légale | C26: =Calculs!D25 -> 900000
A27: IAS 1 | B27: Autres réserves | C27: =Calculs!D26 -> 1500000
A28: IAS 1 | B28: Résultat net de l’exercice – part du groupe (perte) | C28: =Calculs!D47 -> -1389600
B29: Total capitaux propres – part du groupe | C29: =SUM(C25:C28) -> 10010400
B30: INTÉRÊTS MINORITAIRES
A31: IFRS 10 | B31: Réserves des minoritaires | C31: =Calculs!D27 -> 1000000
A32: IFRS 10 | B32: Résultat net – part des minoritaires (20 %) | C32: =Calculs!D46 -> -347400
B33: Total intérêts minoritaires | C33: =SUM(C31:C32) -> 652600
B34: Total capitaux propres (y compris minoritaires) | C34: =C29+C33 -> 10663000
B35: PASSIFS NON COURANTS
A36: IFRS 9 | B36: Emprunts auprès des établissements de crédit – part à plus d’un an | C36: =Calculs!D28-Calculs!D36 -> 900000
B37: Total passifs non courants | C37: =SUM(C36:C36) -> 900000
B38: PASSIFS COURANTS
A39: IFRS 9 | B39: Emprunts auprès des établissements de crédit – part à moins d’un an | C39: =Calculs!D36 -> 300000
A40: IAS 37 | B40: Provisions pour risques et charges (litige salarié, décision dans 4 mois) | C40: =Calculs!D29 -> 180000
A41: IFRS 9 | B41: Fournisseurs et comptes rattachés | C41: =Calculs!D30 -> 1700000
A42: IAS 1 | B42: État, créditeur | C42: =Calculs!D31 -> 250000
...

Sheet Calculs
A1: Calculs préparatoires — Exercice 2 (IAS/IFRS)
A2: Société « X » — au 31/12/2014 — montants en dirhams (MAD). Texte bleu = données de l’énoncé ; noir = formules.
A4: Poste (énoncé) | B4: Brut | C4: Amort. / Prov. | D4: Net
A5: ACTIF
A6: Brevets, marques, droits et valeurs similaires | B6: 1400000 | C6: 280000 | D6: =B6-C6 -> 1120000
A7: Terrains bâtis | B7: 1800000 | C7: 0 | D7: =B7-C7 -> 1800000
A8: Constructions (immeuble mis en location à des tiers) | B8: 1600000 | C8: 320000 | D8: =B8-C8 -> 1280000
A9: ITMO (installations techniques, matériel et outillage) | B9: 5000000 | C9: 2000000 | D9: =B9-C9 -> 3000000
A10: Matériel de transport | B10: 600000 | C10: 480000 | D10: =B10-C10 -> 120000
A11: Mobilier, matériel de bureau et matériel informatique | B11: 300000 | C11: 220000 | D11: =B11-C11 -> 80000
A12: Immobilisations financières – titres de participation | B12: 1000000 | C12: 0 | D12: =B12-C12 -> 1000000
A13: Immobilisations financières – prêt à une filiale | B13: 700000 | C13: 0 | D13: =B13-C13 -> 700000
A14: Stocks de matières et fournitures consommables | B14: 200000 | C14: 0 | D14: =B14-C14 -> 200000
A15: Stocks de produits en cours | B15: 100000 | C15: 0 | D15: =B15-C15 -> 100000
A16: Stocks de produits finis | B16: 500000 | C16: 25000 | D16: =B16-C16 -> 475000
A17: Clients et comptes rattachés | B17: 2800000 | C17: 150000 | D17: =B17-C17 -> 2650000
... A20: Caisse | B20: 250000 | C20: 0 | D20: =B20-C20 -> 250000
A21: Total actif net | D21: =SUM(D6:D20) -> 13993000
A23: CAPITAUX PROPRES ET DETTES (hors résultat)
A24: Capital social | D24: 9000000
A25: Réserve légale | D25: 900000
A26: Autres réserves | D26: 1500000
A27: Réserves des minoritaires | D27: 1000000
A28: Emprunts auprès des établissements de crédit | D28: 1200000
A29: Provisions pour risques et charges (litige avec un salarié) | D29: 180000
A30: Fournisseurs et comptes rattachés | D30: 1700000
A31: État, créditeur | D31: 250000
A32: Total hors résultat | D32: =SUM(D24:D31) -> 15730000
A34: INFORMATIONS COMPLÉMENTAIRES (énoncé)
A35: Prêt à la filiale – part remboursable en juin 2015 (< 12 mois) | D35: 200000
A36: Emprunts (EAEC) – part remboursable à moins de 12 mois | D36: 300000
A37: Part des intérêts minoritaires dans le résultat | D37: 0.2
A38: Créances clients à échéance > 12 mois (information : restent courantes) | D38: 200000
A40: DÉTERMINATION DU RÉSULTAT NET (solde débiteur = perte)
A41: Total actif net | D41: =D21 -> 13993000
A42: Dettes et provisions (emprunts, provisions, fournisseurs, État) | D42: =D28+D29+D30+D31 -> 3330000
A43: Capitaux propres hors résultat | D43: =D24+D25+D26+D27 -> 12400000
A44: Capitaux propres nécessaires pour équilibrer (Actif – dettes) | D44: =D41-D42 -> 10663000
A45: Résultat net de l’exercice, y c. minoritaires | D45: =D44-D43 -> -1737000
A46: dont part des minoritaires (20 %) | D46: =D45*D37 -> -347400
...
